tests/medium_61.in
4
o
3 S 101 AAIE 1375 975
0 S 102 AAIC 208 162
2 S 103 AAIE 1104 923
3 C 101
2 B 105 AA 1424 527
0 S 106 AAID 1881 116
0 S 107 AA 1796 821
2 S 108 AAO 1781 798
1 S 109 AAIN 170 743
3 C 101
0 B 111 AAM 750 999
2 S 112 AA 409 133
3 B 113 AAN 1281 692
3 S 114 A 323 18
0 S 115 AA 1439 524
2 S 116 AAO 566 734
0 S 117 AAO 1204 650
2 C 105
0 B 119 AAC 362 739
2 C 116
2 B 121 AAIC 1768 120
3 C 101
3 B 123 AAM 1853 217
2 B 124 AAC 1931 853
1 C 109
2 B 126 AAC 875 903
2 C 126
2 S 128 AAIE 256 106
0 C 115
3 C 113
3 B 131 AA 126 595
0 C 119
1 B 133 AAID 414 325
0 C 107
1 S 135 AAO 462 782
3 C 101
3 C 131
1 C 135
0 B 139 AAIN 999 454
0 C 107
1 S 141 AAIN 1553 890
2 S 142 AAN 1996 765
3 C 114
1 S 144 AAO 1852 922
0 B 145 AAID 1932 591
3 S 146 AAC 900 73
3 S 147 AAIE 1931 111
2 B 148 AAM 448 975
2 S 149 AAIC 686 810
0 S 150 AAIC 1140 150
1 S 151 AAO 1294 442
2 S 152 AAO 349 170
2 S 153 AAIE 1512 349
3 C 123
2 B 155 AAIE 613 840
1 C 109
0 B 157 AAO 1926 245
3 B 158 AAM 725 147
1 B 159 AAN 1648 700
3 C 147
0 S 161 A 1429 867
1 B 162 AAC 886 762
3 B 163 AAC 1581 466
0 B 164 AAID 1453 564
0 S 165 AAIN 388 445
0 B 166 AAIN 212 799
0 C 115
0 C 165
0 C 166
0 B 170 AAIE 1632 502
1 S 171 A 1753 270
2 C 108
0 S 173 A 1177 112
1 B 174 AAN 1093 468
1 B 175 AAC 519 238
3 B 176 AAO 1506 884
2 S 177 AAIN 1741 407
3 B 178 AAC 209 777
0 B 179 AAIC 246 489
1 S 180 AAIE 1706 759
3 B 181 AA 378 353
2 C 105
1 S 183 AAM 1303 230
2 B 184 AAIE 403 554
2 S 185 AAC 1388 186
3 B 186 AAIE 1356 751
0 B 187 AAO 930 610
2 B 188 AA 236 257
1 S 189 AAO 830 258
3 C 101
3 C 158
3 C 158
1 S 193 AAIC 1203 182
2 S 194 AAO 395 110
1 C 133
0 B 196 AAN 519 306
1 S 197 AAID 991 490
1 B 198 A 679 703
1 S 199 AAIC 1690 556
3 B 200 AAC 1122 184
0 C 119
0 C 115
1 C 199
2 B 204 AAIE 1857 55
1 B 205 AAIE 1760 109
2 S 206 AAID 1840 783
0 C 111
3 S 208 AAIN 1523 882
3 S 209 AAO 1544 483
2 C 149
1 B 211 AAID 880 36
2 B 212 AAIE 205 33
3 B 213 AAC 1039 234
1 C 141
3 B 215 AAN 1349 169
2 B 216 AAIC 1302 132
1 C 198
2 S 218 AAIC 675 277
1 B 219 AAIE 1802 678
3 C 213
0 S 221 AA 457 146
1 C 159
1 C 162
2 C 184
0 S 225 AAN 1310 218
3 B 226 AAM 1814 624
3 C 147
1 S 228 AAM 294 401
2 S 229 AAIN 703 92
2 C 112
2 B 231 AAIE 1527 537
1 C 174
1 S 233 AAM 546 227
0 C 102
3 B 235 AAID 238 210
0 C 157
1 S 237 AAC 1826 437
1 C 159
0 S 239 AAIC 1571 21
3 C 226
1 B 241 AAM 1638 615
1 B 242 AAC 696 105
1 S 243 AAID 1530 437
2 C 206
2 B 245 A 1439 645
0 S 246 AAC 1089 336
2 S 247 AAC 521 383
2 C 124
1 B 249 AAM 352 579
2 S 250 AAM 1369 481
2 S 251 AAIC 1669 138
2 B 252 AAIN 1267 871
0 S 253 AA 103 601
0 C 246
3 C 213
0 S 256 AAC 256 396
2 S 257 AAC 1877 506
2 S 258 AAO 363 698
0 C 139
1 S 260 AAC 688 536
3 B 261 AAIE 618 252
3 C 114
3 B 263 AAC 1483 239
x
