tests/medium_62.in
4
o
1 B 103 AAID 1816 372
2 B 104 AAID 1792 450
2 B 105 AAO 1096 761
1 B 106 AAIN 168 782
1 S 107 AAC 443 703
1 S 108 AAIE 1755 88
2 B 109 AAIC 681 472
2 B 111 AAIC 1908 701
1 B 112 AAID 941 803
0 B 113 AAN 1197 974
3 B 115 AAN 1559 217
0 S 116 AAID 1685 541
3 B 117 AAIE 140 175
1 C 108
0 B 119 AAC 1662 416
2 C 111
2 C 105
3 B 122 AA 1923 27
1 C 112
3 C 117
2 B 125 AAIE 1327 461
3 C 115
0 S 127 AAC 876 848
2 S 128 AAID 1045 91
1 B 129 AAIC 445 637
2 B 130 A 1348 880
0 C 119
2 B 132 AAIN 1278 400
3 S 133 AAIN 1752 203
1 S 134 AA 1635 157
3 C 115
1 S 136 AAM 884 480
1 B 137 AAO 878 263
1 C 112
1 C 112
0 S 140 AAIE 469 668
2 B 141 AAIN 769 432
1 S 142 AAIN 1282 739
2 C 125
3 B 144 AAIE 1828 831
0 B 145 AAID 1545 794
3 S 146 AA 177 644
2 C 132
3 B 148 AAC 1767 904
1 B 149 AAIE 1595 807
0 S 150 AAIC 329 871
3 C 133
1 B 152 AAC 1707 388
2 S 153 AA 1161 868
2 S 154 AAN 105 905
2 C 154
0 S 156 A 385 725
0 C 116
0 B 158 AAID 719 461
2 S 159 AAIE 1671 590
0 B 160 AAM 1823 349
1 B 161 AAO 279 953
1 C 134
3 C 133
1 S 164 AAIC 1625 294
3 C 122
0 C 145
3 B 167 AAM 108 568
3 S 168 AAIE 924 345
2 S 169 AAN 657 350
1 S 170 AAN 1050 833
1 S 171 AAC 1286 751
1 S 172 AAN 1784 703
3 B 173 AAIE 1243 979
1 B 174 AAIE 1103 854
2 C 104
2 B 176 A 544 172
1 C 112
0 B 178 A 1791 311
0 B 179 AAO 1534 531
1 B 180 AAIE 1659 721
0 C 145
1 S 182 AAIC 1534 332
0 S 183 AAM 590 91
0 S 184 AAIE 347 938
1 C 137
1 S 186 AAC 1770 934
0 C 145
1 S 188 AAIN 180 974
1 B 189 AA 296 558
0 S 190 AAIE 214 859
3 S 191 A 1835 995
0 S 192 AAM 956 414
3 B 193 AAID 285 214
1 S 194 AAIN 1209 98
1 S 195 A 1105 156
3 C 168
2 B 197 AAIN 1013 458
0 B 198 AAO 1239 593
3 S 199 A 539 619
2 C 176
x
