tests/medium_63.in
4
o
3 B 101 A 1266 905
2 B 102 AAM^A 1202 503
3 B 103 AAM^A 1381 853
1 S 105 AA 820 889
0 S 106 AAN 1193 673
2 S 107 A 1768 763
2 B 109 AA 286 193
1 S 113 AAIC 824 588
1 B 114 AAN 1236 606
2 B 115 AAIC^B 645 306
2 B 116 AAM^B 1829 849
3 B 117 AAC 1039 680
0 B 118 A 850 681
1 B 119 AAIN 1689 358
0 S 120 AAN 588 395
0 S 122 AAM^B 830 152
2 S 126 AAC 776 764
3 B 127 AAM^A 1389 589
2 B 128 AAIC^B 1426 981
1 S 129 AAIC^B 1814 801
3 S 131 AAIC^B 484 783
2 B 133 AAM^B 1435 954
3 S 134 AA 174 998
3 S 136 AAN 1161 259
3 S 137 AAIC 597 43
2 S 139 AAC 1346 695
3 S 140 AAIC 376 316
0 B 141 AAM^A 1671 900
0 B 142 AAIN 1325 80
0 B 144 AA 1778 603
2 S 145 AAM^A 1614 519
2 S 147 A 1382 321
1 B 148 AAM^A 1440 394
2 S 149 AAIC^B 456 52
0 S 150 AAM^B 142 575
3 B 151 AAIC 1689 743
2 B 152 AAIC^C 1154 545
0 B 154 AAN 662 690
2 S 155 AAC 1234 688
3 S 156 AAIC^C 725 808
0 S 157 AAIN 502 923
0 B 158 AAIC^B 1271 709
2 B 159 AAIC 800 831
3 B 160 AAM^B 542 988
2 B 161 AA 166 903
2 S 162 AAM^A 1372 770
3 S 166 AAIC^C 749 570
3 B 168 A 208 828
1 B 171 AAIC^B 1029 670
2 B 172 A 849 70
0 S 174 AAIC^C 868 49
0 S 175 AAM^B 1063 78
2 B 177 AA 578 617
2 B 179 AAIN 1603 756
1 S 180 AAIC^C 149 442
1 S 181 AAM^B 678 290
1 S 182 A 633 360
1 S 183 AAC 383 724
3 S 184 AAIC^B 1131 347
2 S 185 AAIN 1466 203
2 S 186 AAC 1822 178
3 B 187 A 409 684
3 B 188 AAM^A 1537 127
1 B 190 AAM^B 522 789
1 S 194 AAM^B 1063 960
0 S 196 AAIC^B 1916 953
1 S 197 AAM^B 244 923
1 B 199 AA 938 538
1 S 200 AAIC 1040 706
0 B 201 A 792 809
2 S 202 AAN 1894 751
0 S 203 AAIC^C 389 270
0 S 204 A 1480 692
3 B 205 AA 1115 581
0 S 207 A 796 300
3 B 208 AA 1856 654
2 B 209 AAC 1714 114
3 S 210 AAN 186 34
0 B 213 AAM^B 356 519
0 S 215 AA 1342 730
3 B 216 AAIN 1639 67
1 S 217 AAN 423 996
1 B 218 AAIC^B 1928 226
3 B 219 AA 590 389
0 S 222 AAIN 1362 825
0 B 223 AAM^B 1869 27
3 B 225 AAIC^B 414 197
1 S 227 AAM^A 135 550
3 S 228 AAN 573 758
0 B 229 AAIC^B 1876 982
3 S 230 AAC 1559 363
2 S 231 A 1199 366
3 B 232 AAM^B 993 93
3 B 235 AAIC 1630 267
0 S 236 AAC 1343 793
3 S 237 AA 657 299
2 B 239 AAM^B 861 70
0 B 241 AAM^B 146 563
0 S 242 AA 1292 218
2 B 244 AAIC^B 1700 393
1 S 246 AAIC^C 734 666
1 B 247 AAM^A 188 127
1 B 248 AAIC 1552 650
1 B 251 AAN 1141 609
0 S 253 AAN 1429 507
2 S 254 AAN 629 550
3 B 255 AAM^A 752 55
3 S 256 AAM^A 716 43
0 B 257 AAC 1708 922
2 B 259 AAIN 538 184
0 B 260 AAIC^B 1255 479
0 S 262 AAC 517 307
0 B 264 AAIC^B 1422 743
1 S 265 AA 178 219
0 B 266 AA 1819 352
2 B 268 AAIC 1334 609
3 B 269 AAC 1521 742
2 B 270 AAIC 1014 883
1 B 271 AAM^A 886 201
0 S 272 AA 1255 524
1 B 274 A 597 450
0 B 275 A 1805 302
1 S 276 AAM^A 1233 719
3 S 277 AA 544 625
2 B 279 AA 1361 434
0 B 281 A 1230 287
2 S 283 AAIN 1331 933
0 B 284 AAC 1733 283
0 B 285 AAM^B 1981 240
x
