tests/medium_64.in
4
o
0 B 101 AAID 430 316
1 S 103 AAIN 1645 860
0 S 104 AAM 1397 153
0 B 105 A 333 276
3 S 106 AAO 397 794
3 S 108 AAC 568 338
2 S 109 AAIN 854 790
3 B 110 A 536 907
2 S 111 AA 350 458
3 S 112 AAIN 1411 52
1 S 113 AA 673 917
1 S 114 AAC 436 893
1 B 115 AAM 1708 313
0 C 101
1 C 113
0 B 118 AAO 1989 700
2 C 109
2 B 120 AAIE 361 389
3 S 121 AAIE 1692 938
1 S 122 AAN 203 317
0 B 123 A 1653 489
2 B 124 AAO 949 608
3 B 125 AAID 757 447
0 C 105
1 B 127 AA 111 24
1 S 128 AAM 939 864
3 C 121
0 C 104
0 C 101
3 S 132 AAM 1767 203
1 C 114
1 C 103
0 S 135 AAO 413 386
1 C 103
2 S 137 AAIC 842 35
0 S 138 AAM 1266 68
2 B 139 AAM 965 62
2 B 140 AAM 527 766
2 C 109
3 C 106
3 S 143 AAN 1076 652
3 B 144 A 1058 431
3 C 110
0 B 146 AAIN 1987 38
2 C 137
2 C 111
0 B 149 A 679 333
3 B 150 AA 997 144
1 B 151 A 1555 997
0 C 138
0 B 153 AAIC 1316 186
2 S 154 AA 1179 616
0 B 155 AA 814 306
1 C 122
1 B 157 AAIN 440 892
0 B 158 A 649 30
2 B 159 AAIN 690 688
3 B 160 AAC 1363 863
0 B 161 AAID 639 261
2 B 162 AAID 1481 974
0 B 163 A 1750 343
0 S 164 AAM 275 1000
2 S 165 AAO 687 224
2 C 140
0 C 153
2 S 168 AAID 828 68
0 C 138
2 C 124
3 B 171 AAM 1741 870
2 C 111
0 B 173 AAIN 1627 627
2 S 174 AAC 167 227
0 S 175 AAM 539 841
1 C 114
0 C 138
3 S 178 AAID 174 395
3 S 179 A 698 29
0 B 180 AAN 1662 703
1 C 113
0 S 182 AAM 658 967
1 C 122
0 B 184 AAIE 1401 1000
1 S 185 AAIE 1309 346
0 B 186 AAID 980 988
3 C 150
3 C 110
3 C 150
3 S 190 AAIE 998 476
0 S 191 AAIE 1655 966
3 B 192 AA 745 678
3 C 106
1 S 194 AAID 1025 901
0 B 195 AAM 976 168
3 B 196 AAID 1192 373
3 C 108
1 C 103
3 C 190
0 C 135
1 B 201 AAM 1284 965
2 S 202 AAO 1674 617
1 S 203 AAIC 1474 840
1 S 204 AAM 736 956
3 B 205 AAM 1982 502
2 B 206 AA 182 336
0 S 207 AAIC 1070 427
2 C 154
2 B 209 AAIE 293 912
2 S 210 AAIN 1153 800
2 B 211 A 1016 728
0 B 212 AAN 1236 516
1 C 201
1 S 214 AAO 481 929
3 C 112
0 S 216 AAN 901 638
2 S 217 AAIE 491 337
1 B 218 AAIE 1291 94
3 B 219 AAIC 301 760
2 C 109
3 C 112
3 B 222 AAM 1631 361
3 S 223 AA 1273 602
2 B 224 AAM 1743 290
3 C 110
2 B 226 AA 829 626
2 C 217
1 S 228 AAIE 1931 687
3 C 196
0 S 230 AAIE 471 584
2 B 231 AA 1574 117
3 B 232 AA 555 57
1 B 233 AAM 906 482
0 C 230
3 S 235 AAO 1041 517
0 C 182
1 C 115
0 C 158
2 B 239 A 835 824
0 C 149
1 S 241 A 553 897
3 C 132
1 S 243 AAN 1026 145
1 B 244 AAO 1398 139
3 B 245 A 179 341
0 C 212
0 S 247 AAIN 1873 231
2 B 248 AAN 1147 713
1 B 249 AAM 1824 619
1 S 250 AAIE 623 988
0 B 251 AAIN 1170 627
2 S 252 AAIE 957 141
0 C 158
0 S 254 AA 1450 775
3 B 255 AAIE 655 361
2 C 139
2 C 109
3 B 258 AAO 850 82
3 B 259 A 895 154
2 S 260 AAIC 1162 630
3 B 261 AAO 1666 501
1 B 262 AAIN 1711 540
1 S 263 AAIN 1325 714
1 C 262
0 S 265 AAN 1969 861
0 C 164
2 B 267 AAIE 1514 133
1 B 268 AAO 164 702
1 S 269 AAO 1537 566
0 C 135
3 S 271 AAC 1342 392
2 S 272 AAID 395 136
2 C 210
0 B 274 AAIC 678 727
1 B 275 AAO 319 529
x
