tests/medium_65.in
4
o
3 B 101 AAIC 583 985
0 B 102 AAIN 1632 481
0 B 103 AA 674 937
2 S 104 AAO 624 951
3 C 101
3 B 106 AA 403 349
3 C 106
0 B 109 AAIE 1685 998
0 C 103
1 B 111 AAIE 1964 399
3 C 106
3 C 101
1 C 111
3 C 106
0 B 116 AAO 700 537
1 C 111
3 S 118 AAIN 594 82
2 B 119 AAC 1325 270
1 S 120 AAM 1257 195
2 C 104
3 S 122 AAID 378 554
3 C 106
3 B 124 AAN 1722 722
1 S 125 AAM 1584 681
3 B 126 A 708 800
3 S 127 AAO 1924 21
3 S 128 AAIN 346 906
1 B 129 AAIE 723 298
3 B 130 AAID 534 396
0 B 131 AAN 1646 816
1 B 132 AAN 1835 781
3 S 133 AAIN 1809 355
0 C 131
3 C 101
2 S 136 AAM 1831 765
2 C 119
0 C 103
3 C 128
2 C 119
0 B 141 AAO 1991 676
2 B 142 AAC 1745 107
1 B 143 AAN 281 665
3 S 144 A 713 542
3 S 145 AA 1713 755
3 S 146 AAIE 1090 286
1 B 147 AAID 1110 119
0 B 148 AAIE 814 143
2 C 136
1 B 150 AAIN 222 981
1 S 151 AAC 874 723
2 S 152 AAIC 825 63
3 C 106
0 B 154 AAO 240 944
2 C 119
1 B 156 A 325 696
3 C 145
3 S 158 AA 874 81
2 B 159 AAN 153 824
3 B 160 AAIC 742 983
1 C 120
3 B 162 A 1307 829
0 C 154
0 S 164 AA 707 422
0 B 165 AAIE 1675 624
1 B 166 A 1927 225
2 B 167 AAO 594 858
2 B 168 AAM 155 172
2 S 169 AAO 1499 700
2 C 152
1 S 171 AAIE 727 910
3 C 122
0 S 173 AAM 538 198
1 S 174 AA 556 864
2 S 175 AAID 402 830
0 B 176 AAIE 1468 366
3 B 177 AAC 1113 870
3 S 178 AAM 890 549
2 B 179 AAC 217 400
2 S 180 AAIC 518 599
2 C 167
1 S 182 AAM 324 984
1 S 183 AAID 785 570
2 B 184 AAIN 206 590
0 C 173
1 C 156
2 B 187 AAIE 970 778
1 S 188 AAO 1051 85
2 B 189 AAC 482 219
0 C 131
3 B 191 AAM 734 268
3 B 192 AAIC 210 313
2 B 193 AA 874 955
1 S 194 A 398 280
1 B 195 AAIC 1373 996
3 B 196 AAO 1790 392
2 S 197 AAM 1372 320
0 C 165
3 S 199 AA 1748 244
1 S 200 AAIN 1921 681
1 B 201 AAM 1868 360
3 S 202 AAIE 495 401
0 B 203 AAC 1514 177
3 B 204 AAIE 271 430
2 C 152
3 C 191
1 S 207 AAO 1908 734
1 C 194
0 S 209 AAC 1233 318
3 S 210 A 1766 354
2 B 211 AAIE 1180 764
2 C 189
1 B 213 AAC 1048 438
1 S 214 AAC 1808 943
2 S 215 AAM 525 872
2 C 189
1 B 217 AAM 149 359
1 S 218 AAN 1910 128
2 C 159
2 S 220 AAIN 1051 31
0 S 221 AA 208 676
2 C 167
3 B 223 A 721 788
0 B 224 AAN 353 909
0 C 141
1 S 226 A 1719 980
0 B 227 AAN 1467 743
2 S 228 AAIE 1229 344
0 C 209
3 B 230 AAN 1597 205
1 S 231 AAO 373 714
1 B 232 AAIC 698 677
3 C 133
0 S 234 AAIE 775 60
0 B 235 AAIC 1963 336
2 B 236 AAIE 1417 637
2 C 179
2 C 187
2 C 168
0 C 224
1 B 241 AAN 1086 93
1 S 242 AAO 741 680
0 C 148
0 B 244 AAM 498 361
2 B 245 AAO 864 442
2 B 246 AAN 1474 238
1 S 247 AAC 917 794
3 C 162
1 B 249 AA 673 484
3 S 250 A 1815 35
1 B 251 A 1137 928
2 B 252 AAC 1339 681
3 S 253 AAM 1812 125
0 B 254 AAN 1104 417
3 C 192
3 B 256 AAIC 1508 110
0 B 257 AAIC 1948 580
0 S 258 AAM 425 891
3 B 259 A 693 565
3 C 204
1 B 261 AAO 1732 904
1 C 151
1 S 263 AAIC 1537 586
3 S 264 AAID 1249 483
0 B 265 AAIC 512 51
0 S 266 AAIC 1291 616
3 S 267 AAN 1564 79
2 B 268 AAIC 1822 73
1 S 269 AAM 876 190
2 B 270 AAID 819 689
0 S 271 AAID 986 528
3 C 144
1 S 273 AAIC 1787 561
2 C 159
2 C 187
3 S 276 AAIC 1713 444
0 C 173
0 B 278 AAIN 994 634
1 S 279 AAIE 1635 570
x
