tests/medium_66.in
4
o
3 S 102 AA 440 735
3 B 105 AAO 1897 663
1 S 106 AAID 262 273
1 C 106
3 C 102
0 B 109 AA 1429 900
3 B 110 AAN 149 872
2 B 111 AAC 1400 25
2 B 112 AAIC 1709 489
2 C 112
0 S 114 A 1866 16
0 S 115 AAID 1073 437
0 S 116 AAN 1794 161
0 B 117 AAIE 918 554
2 S 118 AAO 300 851
0 S 119 AAIC 1484 32
2 B 120 AAC 1204 925
1 S 121 AA 544 537
3 S 122 AAO 1823 898
3 B 123 AA 1777 717
2 C 120
3 C 110
0 S 126 AAID 1203 633
0 C 114
1 C 106
0 S 129 AAIC 1117 204
1 C 121
3 S 131 AAO 789 896
1 S 132 A 841 639
0 B 133 AAIN 527 362
2 C 120
2 B 135 AAIE 979 631
2 C 112
1 C 121
3 B 138 AAC 322 825
2 B 139 AA 1659 879
3 B 140 AAO 276 860
1 B 141 AAIC 1607 541
2 C 120
2 S 143 A 1995 648
1 B 144 AAO 1123 45
0 S 145 AAO 1088 313
3 S 146 AAN 1591 867
2 B 147 AAO 1284 406
2 S 148 AAC 1530 73
3 S 149 AAO 1491 916
1 S 150 AAO 765 842
0 S 151 A 435 767
1 C 150
3 B 153 AAM 1921 303
3 B 154 AAO 1196 723
2 C 135
1 B 156 AAC 1048 298
0 C 119
2 C 111
1 S 159 AAM 1313 747
0 B 160 A 742 642
3 S 161 AAIC 1425 568
2 C 148
1 S 163 A 1134 663
0 B 164 A 392 606
0 C 145
2 C 148
0 C 114
3 C 149
3 B 169 AAIN 350 656
0 S 170 A 784 510
0 B 171 A 1812 925
1 S 172 AAIE 1731 417
0 C 109
2 S 174 AAIE 1565 760
2 S 175 AAC 1327 436
2 C 120
1 B 177 AAC 583 740
0 B 178 A 1220 402
1 C 159
3 C 131
2 B 181 AAID 1754 299
2 B 182 AAID 1274 305
3 S 183 AAIC 963 439
1 S 184 AAIN 1979 499
3 B 185 AAIE 1231 643
2 C 181
0 S 187 AAIN 1815 629
0 S 188 A 1594 239
0 C 171
2 C 118
3 B 191 A 349 245
2 B 192 AAM 755 393
3 S 193 AA 201 804
0 S 194 AAN 1669 230
1 B 195 A 955 236
0 S 196 AAN 1948 191
1 C 159
1 B 198 A 1395 91
1 C 132
3 S 200 AAIN 1457 832
0 C 188
0 C 126
2 C 147
1 S 204 AAO 396 196
2 B 205 AAIE 1353 881
2 S 206 A 963 926
1 C 172
2 C 135
3 B 209 AA 1520 108
0 B 210 AAN 251 835
1 S 211 AAID 119 652
1 S 212 AAN 1948 260
1 S 213 AAN 1022 666
3 S 214 AA 1375 54
2 C 205
0 S 216 AAIC 1701 534
3 C 183
3 S 218 AAID 1350 587
3 S 219 AAO 1031 712
2 B 220 AA 771 283
2 C 175
2 B 222 AAO 1004 421
2 C 182
0 B 224 AAIE 1604 574
0 C 178
2 B 226 AAIC 813 210
2 B 227 AAN 1502 757
1 C 213
0 S 229 AAIE 1831 919
3 B 230 AAIC 1063 916
0 C 160
1 S 232 A 1253 581
1 B 233 AAO 1397 331
1 B 234 A 342 528
0 C 109
3 C 214
0 C 115
0 C 115
0 S 239 AAC 327 447
1 C 163
0 S 241 AAIC 225 45
1 B 242 A 1554 794
0 S 243 AAM 454 852
0 S 244 AA 1860 357
1 S 245 AAID 1705 639
2 C 175
2 C 135
0 B 248 AAIE 1482 115
0 C 224
2 S 250 AAC 1449 860
2 S 251 AAC 1091 853
0 C 248
3 S 253 AAM 1199 630
3 B 254 AAIC 1360 239
2 B 255 AAN 1629 771
3 C 253
0 C 116
3 S 258 AAID 1985 163
3 B 259 AAN 1883 453
3 C 214
1 C 233
3 S 262 AAO 796 745
0 S 263 AAID 808 993
2 C 182
2 S 265 AAN 1730 671
1 C 141
2 B 267 AAIN 113 976
1 S 268 AA 1842 265
2 C 175
2 B 270 AAC 1148 547
0 S 271 AAO 1811 492
0 S 272 AAM 121 507
0 B 273 AAIN 523 232
1 B 274 A 218 783
0 B 275 AAIE 1120 462
1 C 274
2 B 277 AAM 1486 126
1 S 278 AAIE 1868 263
2 C 267
3 C 253
1 S 281 AAIE 609 58
0 B 282 AAM 1698 498
3 B 283 A 1216 503
1 S 284 AAC 1912 840
1 B 285 A 597 880
1 C 278
2 S 287 AAIN 1324 937
3 C 105
1 B 289 AAIC 486 981
2 C 147
0 C 178
3 S 292 AAO 1651 288
3 S 293 AAO 214 176
x
