tests/medium_67.in
4
o
3 S 102 AAIE 1667 813
1 B 103 AA 780 789
3 C 102
2 B 105 AAID 932 781
3 S 106 AAIE 1858 462
2 S 107 AAIN 704 918
2 S 108 AA 869 449
3 S 109 AAM 1486 549
1 B 110 AAIN 1845 146
1 S 111 AAC 1186 110
1 S 112 AAIN 1122 1000
1 B 113 AAN 592 434
1 B 114 AAIE 362 48
3 C 109
1 S 116 AAIN 963 339
0 B 117 AAO 1816 430
3 B 118 AAC 1758 802
2 S 119 AAO 1153 483
0 C 117
0 C 117
2 C 105
2 B 123 A 1832 246
2 C 107
3 C 106
3 S 126 AA 742 313
1 S 127 AAID 1431 847
3 S 128 AAN 1942 531
3 C 126
2 S 130 A 534 216
3 S 131 AAIN 646 551
2 C 119
1 S 133 AA 1538 502
2 C 119
0 B 135 AAIE 260 687
0 B 136 AAIN 551 587
2 S 137 AAO 177 31
0 C 117
1 B 139 AA 814 804
3 C 118
1 C 114
2 S 142 AAC 1473 439
1 B 143 AAN 176 573
3 C 106
2 B 145 AAO 868 693
1 C 133
1 B 147 A 1543 114
2 B 148 AAIE 612 154
1 B 149 AA 1154 857
0 C 135
2 B 151 AAID 1260 639
0 C 117
3 B 153 AA 1063 840
0 B 154 A 165 906
0 C 136
3 C 153
0 S 157 AAIC 542 90
2 C 105
1 B 159 AAO 657 938
3 S 160 AAIC 1210 232
3 B 161 AA 1021 166
2 S 162 A 613 501
2 C 123
1 S 164 AAIE 1174 517
0 B 165 AAIE 1392 317
0 S 166 AAIE 1303 162
0 C 117
1 C 149
3 B 169 AAC 699 81
0 S 170 AAIC 1982 16
1 B 171 AAO 390 124
3 S 172 AAIE 1536 801
2 S 173 AAID 859 219
3 C 106
2 C 137
3 C 172
1 B 177 AAIN 408 381
3 C 172
0 S 179 AAIC 233 318
2 S 180 AAM 618 496
1 S 181 A 1192 752
1 S 182 AAM 1490 902
2 S 183 AAIN 688 809
3 S 184 A 446 279
0 C 136
2 S 186 AAIC 331 909
1 S 187 AAN 1091 279
1 B 188 AAIN 639 512
1 C 116
0 S 190 A 358 987
2 B 191 AAO 1363 495
0 C 117
3 C 184
3 S 194 AAIN 667 550
0 C 135
1 C 103
2 B 197 A 1018 162
2 S 198 AA 725 742
2 C 148
2 C 108
2 C 119
0 C 117
0 B 203 AAC 1334 781
1 B 204 AAN 1183 165
3 B 205 AAIC 1008 458
2 B 206 AAO 447 632
3 B 207 AAIC 1651 584
2 S 208 AAO 936 214
3 S 209 AAM 427 376
3 S 210 AAIE 344 935
2 S 211 AAID 1979 166
1 B 212 AAIE 1063 922
1 C 188
1 S 214 AAIE 1152 920
1 S 215 A 326 382
3 S 216 AAID 699 673
3 B 217 AAIC 673 577
2 S 218 AAC 1419 347
0 B 219 A 1046 82
0 B 220 AAIN 230 315
0 S 221 AAIC 419 674
3 C 205
1 S 223 AAIC 155 710
3 S 224 AAC 1062 512
2 C 137
0 C 179
2 S 227 AAN 879 190
0 S 228 AAO 1915 140
0 C 135
1 C 143
1 C 149
2 C 137
3 B 233 AA 394 496
2 C 145
3 S 235 AAIN 120 111
1 B 236 AAO 1992 871
3 S 237 AAC 1993 631
2 C 119
0 S 239 AAIN 829 744
0 C 179
0 S 241 AA 1091 60
2 C 191
3 B 243 AA 870 452
3 S 244 A 1457 22
3 C 205
3 C 109
3 S 247 AAC 324 885
2 B 248 AAIC 891 706
2 S 249 AAC 1385 899
3 S 250 AAN 434 975
2 B 251 AAN 1426 820
2 C 148
3 C 209
1 C 110
1 B 255 AAC 1348 599
2 B 256 AAIE 1001 823
1 C 113
0 B 258 AAIE 263 625
1 B 259 AA 903 289
2 B 260 AAO 737 931
2 C 183
1 B 262 AAID 108 872
2 B 263 AAIN 1739 569
1 S 264 AAN 397 340
3 B 265 AAO 1891 517
x
