tests/medium_68.in
4
o
1 S 102 AHL^E 1776 131
0 B 103 BMA 1937 545
1 S 104 ACCO 1068 28
1 B 106 BIO/B 1158 978
0 B 107 ACDI 453 103
0 B 108 ALC 651 961
3 S 109 ARW 572 899
1 S 110 AA 1429 507
2 S 112 BBDC 1727 564
1 B 113 BML^J 611 640
0 S 114 AHT 1151 916
2 B 116 ATH^B 369 903
1 B 118 AR 552 461
0 S 119 BCSF 495 859
3 S 120 ANF 1852 146
1 S 121 AXS 204 584
2 S 124 AMG 1232 342
0 B 125 ABC 706 257
2 B 126 ACM 846 674
1 S 127 ATAQ 221 133
2 S 128 ASC 1305 22
1 S 129 BKSY 1702 872
0 S 130 ATEN 1832 56
2 S 131 AMAM 1303 319
1 S 132 AWI 1403 201
1 B 135 BHR 1056 550
0 B 137 BBWI 479 175
1 B 138 ALTG^A 1697 536
0 S 139 AEO 1581 519
2 S 141 BHR 235 580
3 B 142 ABR 842 590
0 B 143 AVD 1648 988
0 B 145 ALLG 610 479
0 S 148 ASG 1037 155
1 B 150 ACDI 1940 561
2 B 151 BDC 1600 50
2 B 152 ATHM 759 735
1 B 153 BCC 158 238
3 S 155 BEDU 1682 426
0 B 157 ALL^I 170 922
1 S 158 BEST 1936 191
0 S 159 BBWI 1832 379
2 B 160 BAC^K 1265 287
0 S 162 AHT^F 591 291
0 S 163 BIT 1100 283
1 B 164 ACN 1090 36
1 S 166 AVYA 1275 774
2 B 167 AMPY 338 886
0 B 168 AEM 1223 780
0 S 169 BMA 635 191
2 B 170 AMRX 1046 431
1 B 171 AVD 954 747
2 S 172 ACRE 826 351
1 S 174 AEG 1557 651
0 B 175 AXS^E 1466 117
0 S 176 BGT 1176 497
1 B 179 ANAC 413 478
3 B 183 AOD 1320 368
3 S 185 BAC^N 1011 305
1 B 186 AIG 1854 774
2 S 187 ASB 1206 343
1 B 188 BKT 1554 561
3 B 189 BH 222 697
3 B 190 AGR 680 400
3 B 191 AAIC 1499 534
1 B 192 BC^A 1438 823
3 B 193 BHIL 391 565
3 B 194 BKE 235 787
2 B 197 AMPY 1317 560
1 B 200 BC^A 1585 441
1 S 201 ATGE 1272 724
3 S 202 AVK 743 267
1 B 204 AIN 1521 365
3 S 205 ATO 150 242
3 S 206 BHR^B 976 914
3 B 207 AXTA 1304 838
2 B 209 BEKE 407 961
3 B 212 ACP 1456 839
3 B 216 BHR^B 464 667
0 B 217 AXS 1473 145
2 S 222 BLDR 492 889
3 S 223 BEN 1047 311
1 B 224 AOMR 598 841
0 B 225 ATH^A 560 579
2 S 227 B 1931 312
1 B 228 BC^B 396 517
2 S 229 AGM^D 1116 173
3 B 230 BML^G 1708 531
3 S 232 BLK 1422 828
3 S 234 AMG 1190 982
3 B 235 BHE 1669 864
0 B 238 AIG^A 1060 270
2 S 240 BDJ 1543 252
3 B 241 AGD 222 741
1 S 242 BEPI 1071 878
0 S 243 BGT 1537 393
2 B 245 AGM^F 1061 729
1 B 246 BHIL 224 491
0 S 247 ACV 1447 111
2 S 248 BAC^P 882 305
0 S 249 ASB^E 1989 878
0 B 251 AXP 775 204
1 S 252 BLUA 1554 354
0 S 254 BAC^M 731 475
3 S 255 AGTI 1298 858
1 B 259 AP 1337 99
2 B 260 B 1916 573
0 B 261 AIF 801 560
2 B 262 AOD 1435 638
1 S 265 BAC^N 1306 736
0 B 266 BMEZ 1785 103
1 B 267 AHL^D 1653 874
1 S 268 ALCC 1012 880
2 S 269 AQNU 1911 945
3 B 270 AZO 1711 984
0 B 271 ADC 1992 920
2 S 273 ALLE 160 133
3 B 275 ADC^A 409 332
3 B 276 AIO 1078 281
3 B 277 ABG 220 159
2 B 279 BKSY 1790 361
x
